2018-12-24 21:21:40,039 - logs/hashrate.logs:15 - WARNING - logs/hashrate.logs
2018-12-24 21:21:51,044 - logs/hashrate.logs:15 - WARNING - logs/hashrate.logs
2018-12-24 21:21:51,044 - logs/hashrate.logs:15 - WARNING - logs/hashrate.logs
2018-12-24 21:23:47,677 - logs/hashrate.logs:72 - ERROR - hashrate_plot:
Traceback (most recent call last):
  File "/home/andre/anaconda3/envs/bokeh_aion_analytics/lib/python3.5/site-packages/dask/dataframe/utils.py", line 137, in raise_on_meta_error
    yield
  File "/home/andre/anaconda3/envs/bokeh_aion_analytics/lib/python3.5/site-packages/dask/dataframe/core.py", line 3583, in _emulate
    return func(*_extract_meta(args, True), **_extract_meta(kwargs, True))
  File "/home/andre/anaconda3/envs/bokeh_aion_analytics/lib/python3.5/site-packages/dask/utils.py", line 688, in __call__
    return getattr(obj, self.method)(*args, **kwargs)
  File "/home/andre/anaconda3/envs/bokeh_aion_analytics/lib/python3.5/site-packages/pandas/core/frame.py", line 4139, in reset_index
    new_obj.insert(0, name, level_values)
  File "/home/andre/anaconda3/envs/bokeh_aion_analytics/lib/python3.5/site-packages/pandas/core/frame.py", line 3222, in insert
    allow_duplicates=allow_duplicates)
  File "/home/andre/anaconda3/envs/bokeh_aion_analytics/lib/python3.5/site-packages/pandas/core/internals.py", line 4338, in insert
    raise ValueError('cannot insert {}, already exists'.format(item))
ValueError: cannot insert level_0, already exists

During handling of the above exception, another exception occurred:

Traceback (most recent call last):
  File "/home/andre/aion/data_science/bokeh/aion_analytics/scripts/dashboards/hashrate.py", line 67, in hashrate_plot
    title='Hashrate',width=1000, height=600)
  File "/home/andre/anaconda3/envs/bokeh_aion_analytics/lib/python3.5/site-packages/hvplot/__init__.py", line 130, in line
    return self(x, y, kind='line', **kwds)
  File "/home/andre/anaconda3/envs/bokeh_aion_analytics/lib/python3.5/site-packages/hvplot/__init__.py", line 88, in __call__
    self._data, x, y, kind=kind, **params
  File "/home/andre/anaconda3/envs/bokeh_aion_analytics/lib/python3.5/site-packages/hvplot/converter.py", line 140, in __init__
    hover_cols, kwds)
  File "/home/andre/anaconda3/envs/bokeh_aion_analytics/lib/python3.5/site-packages/hvplot/converter.py", line 345, in _process_data
    indexes = [c for c in self.data.reset_index().columns
  File "/home/andre/anaconda3/envs/bokeh_aion_analytics/lib/python3.5/site-packages/dask/dataframe/core.py", line 431, in reset_index
    return self.map_partitions(M.reset_index, drop=drop).clear_divisions()
  File "/home/andre/anaconda3/envs/bokeh_aion_analytics/lib/python3.5/site-packages/dask/dataframe/core.py", line 581, in map_partitions
    return map_partitions(func, self, *args, **kwargs)
  File "/home/andre/anaconda3/envs/bokeh_aion_analytics/lib/python3.5/site-packages/dask/dataframe/core.py", line 3619, in map_partitions
    meta = _emulate(func, *args, udf=True, **kwargs)
  File "/home/andre/anaconda3/envs/bokeh_aion_analytics/lib/python3.5/site-packages/dask/dataframe/core.py", line 3583, in _emulate
    return func(*_extract_meta(args, True), **_extract_meta(kwargs, True))
  File "/home/andre/anaconda3/envs/bokeh_aion_analytics/lib/python3.5/contextlib.py", line 77, in __exit__
    self.gen.throw(type, value, traceback)
  File "/home/andre/anaconda3/envs/bokeh_aion_analytics/lib/python3.5/site-packages/dask/dataframe/utils.py", line 154, in raise_on_meta_error
    raise ValueError(msg)
ValueError: Metadata inference failed in `reset_index`.

You have supplied a custom function and Dask is unable to 
determine the type of output that that function returns. 

To resolve this please provide a meta= keyword.
The docstring of the Dask function you ran should have more information.

Original error is below:
------------------------
ValueError('cannot insert level_0, already exists',)

Traceback:
---------
  File "/home/andre/anaconda3/envs/bokeh_aion_analytics/lib/python3.5/site-packages/dask/dataframe/utils.py", line 137, in raise_on_meta_error
    yield
  File "/home/andre/anaconda3/envs/bokeh_aion_analytics/lib/python3.5/site-packages/dask/dataframe/core.py", line 3583, in _emulate
    return func(*_extract_meta(args, True), **_extract_meta(kwargs, True))
  File "/home/andre/anaconda3/envs/bokeh_aion_analytics/lib/python3.5/site-packages/dask/utils.py", line 688, in __call__
    return getattr(obj, self.method)(*args, **kwargs)
  File "/home/andre/anaconda3/envs/bokeh_aion_analytics/lib/python3.5/site-packages/pandas/core/frame.py", line 4139, in reset_index
    new_obj.insert(0, name, level_values)
  File "/home/andre/anaconda3/envs/bokeh_aion_analytics/lib/python3.5/site-packages/pandas/core/frame.py", line 3222, in insert
    allow_duplicates=allow_duplicates)
  File "/home/andre/anaconda3/envs/bokeh_aion_analytics/lib/python3.5/site-packages/pandas/core/internals.py", line 4338, in insert
    raise ValueError('cannot insert {}, already exists'.format(item))

2018-12-24 21:23:47,677 - logs/hashrate.logs:72 - ERROR - hashrate_plot:
Traceback (most recent call last):
  File "/home/andre/anaconda3/envs/bokeh_aion_analytics/lib/python3.5/site-packages/dask/dataframe/utils.py", line 137, in raise_on_meta_error
    yield
  File "/home/andre/anaconda3/envs/bokeh_aion_analytics/lib/python3.5/site-packages/dask/dataframe/core.py", line 3583, in _emulate
    return func(*_extract_meta(args, True), **_extract_meta(kwargs, True))
  File "/home/andre/anaconda3/envs/bokeh_aion_analytics/lib/python3.5/site-packages/dask/utils.py", line 688, in __call__
    return getattr(obj, self.method)(*args, **kwargs)
  File "/home/andre/anaconda3/envs/bokeh_aion_analytics/lib/python3.5/site-packages/pandas/core/frame.py", line 4139, in reset_index
    new_obj.insert(0, name, level_values)
  File "/home/andre/anaconda3/envs/bokeh_aion_analytics/lib/python3.5/site-packages/pandas/core/frame.py", line 3222, in insert
    allow_duplicates=allow_duplicates)
  File "/home/andre/anaconda3/envs/bokeh_aion_analytics/lib/python3.5/site-packages/pandas/core/internals.py", line 4338, in insert
    raise ValueError('cannot insert {}, already exists'.format(item))
ValueError: cannot insert level_0, already exists

During handling of the above exception, another exception occurred:

Traceback (most recent call last):
  File "/home/andre/aion/data_science/bokeh/aion_analytics/scripts/dashboards/hashrate.py", line 67, in hashrate_plot
    title='Hashrate',width=1000, height=600)
  File "/home/andre/anaconda3/envs/bokeh_aion_analytics/lib/python3.5/site-packages/hvplot/__init__.py", line 130, in line
    return self(x, y, kind='line', **kwds)
  File "/home/andre/anaconda3/envs/bokeh_aion_analytics/lib/python3.5/site-packages/hvplot/__init__.py", line 88, in __call__
    self._data, x, y, kind=kind, **params
  File "/home/andre/anaconda3/envs/bokeh_aion_analytics/lib/python3.5/site-packages/hvplot/converter.py", line 140, in __init__
    hover_cols, kwds)
  File "/home/andre/anaconda3/envs/bokeh_aion_analytics/lib/python3.5/site-packages/hvplot/converter.py", line 345, in _process_data
    indexes = [c for c in self.data.reset_index().columns
  File "/home/andre/anaconda3/envs/bokeh_aion_analytics/lib/python3.5/site-packages/dask/dataframe/core.py", line 431, in reset_index
    return self.map_partitions(M.reset_index, drop=drop).clear_divisions()
  File "/home/andre/anaconda3/envs/bokeh_aion_analytics/lib/python3.5/site-packages/dask/dataframe/core.py", line 581, in map_partitions
    return map_partitions(func, self, *args, **kwargs)
  File "/home/andre/anaconda3/envs/bokeh_aion_analytics/lib/python3.5/site-packages/dask/dataframe/core.py", line 3619, in map_partitions
    meta = _emulate(func, *args, udf=True, **kwargs)
  File "/home/andre/anaconda3/envs/bokeh_aion_analytics/lib/python3.5/site-packages/dask/dataframe/core.py", line 3583, in _emulate
    return func(*_extract_meta(args, True), **_extract_meta(kwargs, True))
  File "/home/andre/anaconda3/envs/bokeh_aion_analytics/lib/python3.5/contextlib.py", line 77, in __exit__
    self.gen.throw(type, value, traceback)
  File "/home/andre/anaconda3/envs/bokeh_aion_analytics/lib/python3.5/site-packages/dask/dataframe/utils.py", line 154, in raise_on_meta_error
    raise ValueError(msg)
ValueError: Metadata inference failed in `reset_index`.

You have supplied a custom function and Dask is unable to 
determine the type of output that that function returns. 

To resolve this please provide a meta= keyword.
The docstring of the Dask function you ran should have more information.

Original error is below:
------------------------
ValueError('cannot insert level_0, already exists',)

Traceback:
---------
  File "/home/andre/anaconda3/envs/bokeh_aion_analytics/lib/python3.5/site-packages/dask/dataframe/utils.py", line 137, in raise_on_meta_error
    yield
  File "/home/andre/anaconda3/envs/bokeh_aion_analytics/lib/python3.5/site-packages/dask/dataframe/core.py", line 3583, in _emulate
    return func(*_extract_meta(args, True), **_extract_meta(kwargs, True))
  File "/home/andre/anaconda3/envs/bokeh_aion_analytics/lib/python3.5/site-packages/dask/utils.py", line 688, in __call__
    return getattr(obj, self.method)(*args, **kwargs)
  File "/home/andre/anaconda3/envs/bokeh_aion_analytics/lib/python3.5/site-packages/pandas/core/frame.py", line 4139, in reset_index
    new_obj.insert(0, name, level_values)
  File "/home/andre/anaconda3/envs/bokeh_aion_analytics/lib/python3.5/site-packages/pandas/core/frame.py", line 3222, in insert
    allow_duplicates=allow_duplicates)
  File "/home/andre/anaconda3/envs/bokeh_aion_analytics/lib/python3.5/site-packages/pandas/core/internals.py", line 4338, in insert
    raise ValueError('cannot insert {}, already exists'.format(item))

2018-12-24 21:23:47,686 - logs/hashrate.logs:179 - ERROR - rendering err:
Traceback (most recent call last):
  File "/home/andre/aion/data_science/bokeh/aion_analytics/scripts/dashboards/hashrate.py", line 160, in hashrate_tab
    hash_plot = renderer.get_plot(dmap_hashrate)
  File "/home/andre/anaconda3/envs/bokeh_aion_analytics/lib/python3.5/site-packages/holoviews/plotting/bokeh/renderer.py", line 162, in get_plot
    plot = super(BokehRenderer, self_or_cls).get_plot(obj, renderer, **kwargs)
  File "/home/andre/anaconda3/envs/bokeh_aion_analytics/lib/python3.5/site-packages/holoviews/plotting/renderer.py", line 182, in get_plot
    initialize_dynamic(obj)
  File "/home/andre/anaconda3/envs/bokeh_aion_analytics/lib/python3.5/site-packages/holoviews/plotting/util.py", line 244, in initialize_dynamic
    dmap[dmap._initial_key()]
  File "/home/andre/anaconda3/envs/bokeh_aion_analytics/lib/python3.5/site-packages/holoviews/core/spaces.py", line 1132, in __getitem__
    val = self._execute_callback(*tuple_key)
  File "/home/andre/anaconda3/envs/bokeh_aion_analytics/lib/python3.5/site-packages/holoviews/core/spaces.py", line 911, in _execute_callback
    retval = self.callback(*args, **kwargs)
  File "/home/andre/anaconda3/envs/bokeh_aion_analytics/lib/python3.5/site-packages/holoviews/core/spaces.py", line 574, in __call__
    ret = self.callable(*args, **kwargs)
  File "/home/andre/anaconda3/envs/bokeh_aion_analytics/lib/python3.5/site-packages/holoviews/util/__init__.py", line 437, in dynamic_operation
    return self._process(map_obj[key], key)
  File "/home/andre/anaconda3/envs/bokeh_aion_analytics/lib/python3.5/site-packages/holoviews/core/spaces.py", line 1135, in __getitem__
    self._cache(tuple_key, val)
  File "/home/andre/anaconda3/envs/bokeh_aion_analytics/lib/python3.5/site-packages/holoviews/core/spaces.py", line 1181, in _cache
    self[key] = val
  File "/home/andre/anaconda3/envs/bokeh_aion_analytics/lib/python3.5/site-packages/holoviews/core/ndmapping.py", line 518, in __setitem__
    self._add_item(key, value, update=False)
  File "/home/andre/anaconda3/envs/bokeh_aion_analytics/lib/python3.5/site-packages/holoviews/core/ndmapping.py", line 160, in _add_item
    self._item_check(dim_vals, data)
  File "/home/andre/anaconda3/envs/bokeh_aion_analytics/lib/python3.5/site-packages/holoviews/core/ndmapping.py", line 820, in _item_check
    super(UniformNdMapping, self)._item_check(dim_vals, data)
  File "/home/andre/anaconda3/envs/bokeh_aion_analytics/lib/python3.5/site-packages/holoviews/core/ndmapping.py", line 143, in _item_check
    restr=data_type))
TypeError: DynamicMap does not accept NoneType type, data elements have to be a ('ViewableElement', 'NdMapping', 'Layout').
2018-12-24 21:23:47,686 - logs/hashrate.logs:179 - ERROR - rendering err:
Traceback (most recent call last):
  File "/home/andre/aion/data_science/bokeh/aion_analytics/scripts/dashboards/hashrate.py", line 160, in hashrate_tab
    hash_plot = renderer.get_plot(dmap_hashrate)
  File "/home/andre/anaconda3/envs/bokeh_aion_analytics/lib/python3.5/site-packages/holoviews/plotting/bokeh/renderer.py", line 162, in get_plot
    plot = super(BokehRenderer, self_or_cls).get_plot(obj, renderer, **kwargs)
  File "/home/andre/anaconda3/envs/bokeh_aion_analytics/lib/python3.5/site-packages/holoviews/plotting/renderer.py", line 182, in get_plot
    initialize_dynamic(obj)
  File "/home/andre/anaconda3/envs/bokeh_aion_analytics/lib/python3.5/site-packages/holoviews/plotting/util.py", line 244, in initialize_dynamic
    dmap[dmap._initial_key()]
  File "/home/andre/anaconda3/envs/bokeh_aion_analytics/lib/python3.5/site-packages/holoviews/core/spaces.py", line 1132, in __getitem__
    val = self._execute_callback(*tuple_key)
  File "/home/andre/anaconda3/envs/bokeh_aion_analytics/lib/python3.5/site-packages/holoviews/core/spaces.py", line 911, in _execute_callback
    retval = self.callback(*args, **kwargs)
  File "/home/andre/anaconda3/envs/bokeh_aion_analytics/lib/python3.5/site-packages/holoviews/core/spaces.py", line 574, in __call__
    ret = self.callable(*args, **kwargs)
  File "/home/andre/anaconda3/envs/bokeh_aion_analytics/lib/python3.5/site-packages/holoviews/util/__init__.py", line 437, in dynamic_operation
    return self._process(map_obj[key], key)
  File "/home/andre/anaconda3/envs/bokeh_aion_analytics/lib/python3.5/site-packages/holoviews/core/spaces.py", line 1135, in __getitem__
    self._cache(tuple_key, val)
  File "/home/andre/anaconda3/envs/bokeh_aion_analytics/lib/python3.5/site-packages/holoviews/core/spaces.py", line 1181, in _cache
    self[key] = val
  File "/home/andre/anaconda3/envs/bokeh_aion_analytics/lib/python3.5/site-packages/holoviews/core/ndmapping.py", line 518, in __setitem__
    self._add_item(key, value, update=False)
  File "/home/andre/anaconda3/envs/bokeh_aion_analytics/lib/python3.5/site-packages/holoviews/core/ndmapping.py", line 160, in _add_item
    self._item_check(dim_vals, data)
  File "/home/andre/anaconda3/envs/bokeh_aion_analytics/lib/python3.5/site-packages/holoviews/core/ndmapping.py", line 820, in _item_check
    super(UniformNdMapping, self)._item_check(dim_vals, data)
  File "/home/andre/anaconda3/envs/bokeh_aion_analytics/lib/python3.5/site-packages/holoviews/core/ndmapping.py", line 143, in _item_check
    restr=data_type))
TypeError: DynamicMap does not accept NoneType type, data elements have to be a ('ViewableElement', 'NdMapping', 'Layout').
