2018-12-12 23:31:46,646 - logs/main.logs:15 - WARNING - logs/main.logs
2018-12-12 23:37:51,949 - logs/main.logs:15 - WARNING - logs/main.logs
2018-12-12 23:44:44,726 - logs/main.logs:15 - WARNING - logs/main.logs
2018-12-12 23:47:49,959 - logs/main.logs:15 - WARNING - logs/main.logs
2018-12-12 23:50:53,941 - logs/main.logs:15 - WARNING - logs/main.logs
2018-12-12 23:53:34,463 - logs/main.logs:15 - WARNING - logs/main.logs
2018-12-13 00:03:31,858 - logs/main.logs:15 - WARNING - logs/main.logs
2018-12-13 00:20:27,087 - logs/main.logs:15 - WARNING - logs/main.logs
2018-12-13 00:30:14,325 - logs/main.logs:15 - WARNING - logs/main.logs
2018-12-13 00:31:43,639 - logs/main.logs:15 - WARNING - logs/main.logs
2018-12-13 00:32:32,780 - logs/main.logs:63 - ERROR - TABS:
Traceback (most recent call last):
  File "/home/andre/aion/data_science/bokeh/aion_analytics/scripts/dashboards/streaming/poolminer_test.py", line 206, in poolminer_tab
  File "/home/andre/anaconda3/envs/bokeh_aion_analytics/lib/python3.5/site-packages/holoviews/core/spaces.py", line 772, in __init__
    self.streams)
  File "/home/andre/anaconda3/envs/bokeh_aion_analytics/lib/python3.5/site-packages/holoviews/core/util.py", line 316, in validate_dynamic_argspec
    unassigned=unassigned))
KeyError: "Callable '<bound method poolminer_tab.<locals>.Poolminer.view_topN of <scripts.dashboards.streaming.poolminer_test.poolminer_tab.<locals>.Poolminer object at 0x7f12223256a0>>' missing keywords to accept stream parameters: start_date,end_date"

During handling of the above exception, another exception occurred:

Traceback (most recent call last):
  File "/home/andre/aion/data_science/bokeh/aion_analytics/main.py", line 56, in aion_analytics
    pm = yield poolminer_tab()
  File "/home/andre/anaconda3/envs/bokeh_aion_analytics/lib/python3.5/site-packages/tornado/gen.py", line 1133, in run
    value = future.result()
  File "/home/andre/anaconda3/envs/bokeh_aion_analytics/lib/python3.5/asyncio/futures.py", line 294, in result
    raise self._exception
  File "/home/andre/anaconda3/envs/bokeh_aion_analytics/lib/python3.5/site-packages/tornado/gen.py", line 307, in wrapper
    result = func(*args, **kwargs)
  File "/home/andre/anaconda3/envs/bokeh_aion_analytics/lib/python3.5/types.py", line 243, in wrapped
    coro = func(*args, **kwargs)
  File "/home/andre/aion/data_science/bokeh/aion_analytics/scripts/dashboards/streaming/poolminer_test.py", line 225, in poolminer_tab
  File "/home/andre/aion/data_science/bokeh/aion_analytics/scripts/utils/myutils.py", line 88, in tab_error_flag
    print('IN POOLMINER')
BrokenPipeError: [Errno 32] Broken pipe
2018-12-13 00:41:19,860 - logs/main.logs:15 - WARNING - logs/main.logs
2018-12-13 00:43:21,811 - logs/main.logs:15 - WARNING - logs/main.logs
2018-12-13 01:04:07,971 - logs/main.logs:15 - WARNING - logs/main.logs
2018-12-13 01:06:06,434 - logs/main.logs:15 - WARNING - logs/main.logs
2018-12-13 08:32:51,698 - logs/main.logs:15 - WARNING - logs/main.logs
2018-12-13 08:36:02,063 - logs/main.logs:15 - WARNING - logs/main.logs
2018-12-13 11:08:09,758 - logs/main.logs:15 - WARNING - logs/main.logs
2018-12-13 13:48:06,381 - logs/main.logs:15 - WARNING - logs/main.logs
2018-12-13 13:50:11,386 - logs/main.logs:15 - WARNING - logs/main.logs
2018-12-13 13:52:32,440 - logs/main.logs:15 - WARNING - logs/main.logs
2018-12-13 13:59:41,529 - logs/main.logs:15 - WARNING - logs/main.logs
2018-12-13 14:38:29,281 - logs/main.logs:15 - WARNING - logs/main.logs
2018-12-13 15:09:27,215 - logs/main.logs:15 - WARNING - logs/main.logs
2018-12-13 15:11:51,907 - logs/main.logs:15 - WARNING - logs/main.logs
2018-12-13 15:14:18,595 - logs/main.logs:15 - WARNING - logs/main.logs
2018-12-13 15:42:46,493 - logs/main.logs:15 - WARNING - logs/main.logs
2018-12-13 15:49:06,247 - logs/main.logs:15 - WARNING - logs/main.logs
2018-12-13 15:51:56,589 - logs/main.logs:15 - WARNING - logs/main.logs
2018-12-13 15:53:12,171 - logs/main.logs:15 - WARNING - logs/main.logs
2018-12-13 15:54:25,872 - logs/main.logs:15 - WARNING - logs/main.logs
2018-12-13 16:11:11,916 - logs/main.logs:15 - WARNING - logs/main.logs
2018-12-13 16:16:20,093 - logs/main.logs:15 - WARNING - logs/main.logs
2018-12-13 16:21:03,247 - logs/main.logs:15 - WARNING - logs/main.logs
2018-12-13 16:32:02,014 - logs/main.logs:15 - WARNING - logs/main.logs
2018-12-13 16:33:10,285 - logs/main.logs:15 - WARNING - logs/main.logs
2018-12-13 16:35:31,433 - logs/main.logs:15 - WARNING - logs/main.logs
2018-12-13 16:49:01,091 - logs/main.logs:15 - WARNING - logs/main.logs
2018-12-13 16:53:36,358 - logs/main.logs:15 - WARNING - logs/main.logs
2018-12-13 16:55:48,647 - logs/main.logs:15 - WARNING - logs/main.logs
2018-12-13 16:57:37,102 - logs/main.logs:15 - WARNING - logs/main.logs
2018-12-13 16:59:07,496 - logs/main.logs:15 - WARNING - logs/main.logs
2018-12-13 17:05:06,493 - logs/main.logs:15 - WARNING - logs/main.logs
2018-12-13 17:05:58,181 - logs/main.logs:15 - WARNING - logs/main.logs
2018-12-13 17:41:52,554 - logs/main.logs:15 - WARNING - logs/main.logs
2018-12-13 17:57:19,248 - logs/main.logs:15 - WARNING - logs/main.logs
2018-12-13 17:59:02,314 - logs/main.logs:15 - WARNING - logs/main.logs
2018-12-13 18:13:07,961 - logs/main.logs:15 - WARNING - logs/main.logs
2018-12-13 18:17:25,960 - logs/main.logs:15 - WARNING - logs/main.logs
2018-12-13 18:21:07,588 - logs/main.logs:15 - WARNING - logs/main.logs
2018-12-13 18:23:34,620 - logs/main.logs:15 - WARNING - logs/main.logs
2018-12-13 18:26:25,829 - logs/main.logs:15 - WARNING - logs/main.logs
2018-12-13 18:28:24,348 - logs/main.logs:15 - WARNING - logs/main.logs
2018-12-13 18:30:52,710 - logs/main.logs:15 - WARNING - logs/main.logs
2018-12-13 18:33:24,163 - logs/main.logs:15 - WARNING - logs/main.logs
2018-12-13 18:36:24,058 - logs/main.logs:15 - WARNING - logs/main.logs
2018-12-13 18:38:47,691 - logs/main.logs:15 - WARNING - logs/main.logs
2018-12-13 18:44:22,084 - logs/main.logs:15 - WARNING - logs/main.logs
2018-12-13 18:44:22,421 - logs/main.logs:63 - ERROR - TABS:
Traceback (most recent call last):
  File "/home/andre/aion/data_science/bokeh/aion_analytics/main.py", line 56, in aion_analytics
    pm = yield poolminer_tab()
  File "/home/andre/anaconda3/envs/bokeh_aion_analytics/lib/python3.5/site-packages/tornado/gen.py", line 1133, in run
    value = future.result()
  File "/home/andre/anaconda3/envs/bokeh_aion_analytics/lib/python3.5/asyncio/futures.py", line 294, in result
    raise self._exception
  File "/home/andre/anaconda3/envs/bokeh_aion_analytics/lib/python3.5/site-packages/tornado/gen.py", line 307, in wrapper
    result = func(*args, **kwargs)
  File "/home/andre/anaconda3/envs/bokeh_aion_analytics/lib/python3.5/types.py", line 243, in wrapped
    coro = func(*args, **kwargs)
  File "/home/andre/aion/data_science/bokeh/aion_analytics/scripts/dashboards/streaming/poolminer.py", line 51, in poolminer_tab
    block_number=[])
  File "/home/andre/anaconda3/envs/bokeh_aion_analytics/lib/python3.5/site-packages/bokeh/models/sources.py", line 130, in __init__
    super(ColumnDataSource, self).__init__(**kw)
  File "/home/andre/anaconda3/envs/bokeh_aion_analytics/lib/python3.5/site-packages/bokeh/model.py", line 219, in __init__
    super(Model, self).__init__(**kwargs)
  File "/home/andre/anaconda3/envs/bokeh_aion_analytics/lib/python3.5/site-packages/bokeh/core/has_props.py", line 236, in __init__
    setattr(self, name, value)
  File "/home/andre/anaconda3/envs/bokeh_aion_analytics/lib/python3.5/site-packages/bokeh/core/has_props.py", line 271, in __setattr__
    (name, self.__class__.__name__, text, nice_join(matches)))
AttributeError: unexpected attribute 'block_number' to ColumnDataSource, possible attributes are callback, data, js_event_callbacks, js_property_callbacks, name, selected, selection_policy, subscribed_events or tags
2018-12-13 18:45:05,287 - logs/main.logs:15 - WARNING - logs/main.logs
2018-12-13 18:45:05,910 - logs/main.logs:63 - ERROR - TABS:
Traceback (most recent call last):
  File "/home/andre/aion/data_science/bokeh/aion_analytics/main.py", line 56, in aion_analytics
    pm = yield poolminer_tab()
  File "/home/andre/anaconda3/envs/bokeh_aion_analytics/lib/python3.5/site-packages/tornado/gen.py", line 1133, in run
    value = future.result()
  File "/home/andre/anaconda3/envs/bokeh_aion_analytics/lib/python3.5/asyncio/futures.py", line 294, in result
    raise self._exception
  File "/home/andre/anaconda3/envs/bokeh_aion_analytics/lib/python3.5/site-packages/tornado/gen.py", line 307, in wrapper
    result = func(*args, **kwargs)
  File "/home/andre/anaconda3/envs/bokeh_aion_analytics/lib/python3.5/types.py", line 243, in wrapped
    coro = func(*args, **kwargs)
  File "/home/andre/aion/data_science/bokeh/aion_analytics/scripts/dashboards/streaming/poolminer.py", line 51, in poolminer_tab
    block_number=[])
  File "/home/andre/anaconda3/envs/bokeh_aion_analytics/lib/python3.5/site-packages/bokeh/models/sources.py", line 130, in __init__
    super(ColumnDataSource, self).__init__(**kw)
  File "/home/andre/anaconda3/envs/bokeh_aion_analytics/lib/python3.5/site-packages/bokeh/model.py", line 219, in __init__
    super(Model, self).__init__(**kwargs)
  File "/home/andre/anaconda3/envs/bokeh_aion_analytics/lib/python3.5/site-packages/bokeh/core/has_props.py", line 236, in __init__
    setattr(self, name, value)
  File "/home/andre/anaconda3/envs/bokeh_aion_analytics/lib/python3.5/site-packages/bokeh/core/has_props.py", line 271, in __setattr__
    (name, self.__class__.__name__, text, nice_join(matches)))
AttributeError: unexpected attribute 'block_number' to ColumnDataSource, possible attributes are callback, data, js_event_callbacks, js_property_callbacks, name, selected, selection_policy, subscribed_events or tags
2018-12-13 18:46:22,262 - logs/main.logs:15 - WARNING - logs/main.logs
2018-12-13 18:48:30,035 - logs/main.logs:15 - WARNING - logs/main.logs
2018-12-13 21:06:23,302 - logs/main.logs:15 - WARNING - logs/main.logs
2018-12-14 13:10:40,201 - logs/main.logs:15 - WARNING - logs/main.logs
2018-12-14 14:56:17,933 - logs/main.logs:15 - WARNING - logs/main.logs
2018-12-15 06:34:26,154 - logs/main.logs:15 - WARNING - logs/main.logs
2018-12-15 06:37:31,428 - logs/main.logs:15 - WARNING - logs/main.logs
2018-12-15 06:55:46,442 - logs/main.logs:15 - WARNING - logs/main.logs
2018-12-15 07:02:01,702 - logs/main.logs:15 - WARNING - logs/main.logs
2018-12-15 07:27:53,439 - logs/main.logs:15 - WARNING - logs/main.logs
2018-12-15 07:32:38,623 - logs/main.logs:15 - WARNING - logs/main.logs
2018-12-15 07:37:35,354 - logs/main.logs:15 - WARNING - logs/main.logs
