2018-12-18 19:10:56,609 - logs/main.logs:15 - WARNING - logs/main.logs
2018-12-18 19:14:32,939 - logs/main.logs:15 - WARNING - logs/main.logs
2018-12-18 19:16:27,944 - logs/main.logs:15 - WARNING - logs/main.logs
2018-12-18 19:17:51,574 - logs/main.logs:15 - WARNING - logs/main.logs
2018-12-18 20:17:17,143 - logs/main.logs:15 - WARNING - logs/main.logs
2018-12-18 20:43:04,383 - logs/main.logs:15 - WARNING - logs/main.logs
2018-12-18 20:46:02,980 - logs/main.logs:15 - WARNING - logs/main.logs
2018-12-18 20:51:21,968 - logs/main.logs:15 - WARNING - logs/main.logs
2018-12-18 20:53:57,150 - logs/main.logs:15 - WARNING - logs/main.logs
2018-12-18 21:29:06,781 - logs/main.logs:15 - WARNING - logs/main.logs
2018-12-18 21:32:43,998 - logs/main.logs:15 - WARNING - logs/main.logs
2018-12-18 21:39:14,115 - logs/main.logs:15 - WARNING - logs/main.logs
2018-12-18 21:48:20,526 - logs/main.logs:15 - WARNING - logs/main.logs
2018-12-18 21:51:21,707 - logs/main.logs:15 - WARNING - logs/main.logs
2018-12-18 21:53:06,737 - logs/main.logs:15 - WARNING - logs/main.logs
2018-12-18 21:55:48,075 - logs/main.logs:15 - WARNING - logs/main.logs
2018-12-18 22:03:30,971 - logs/main.logs:15 - WARNING - logs/main.logs
2018-12-18 22:21:07,949 - logs/main.logs:15 - WARNING - logs/main.logs
2018-12-18 22:22:13,502 - logs/main.logs:15 - WARNING - logs/main.logs
2018-12-18 22:24:45,393 - logs/main.logs:15 - WARNING - logs/main.logs
2018-12-18 22:28:16,649 - logs/main.logs:15 - WARNING - logs/main.logs
2018-12-18 22:29:52,543 - logs/main.logs:15 - WARNING - logs/main.logs
2018-12-18 22:31:41,345 - logs/main.logs:15 - WARNING - logs/main.logs
2018-12-18 22:37:35,047 - logs/main.logs:15 - WARNING - logs/main.logs
2018-12-18 22:42:53,896 - logs/main.logs:15 - WARNING - logs/main.logs
2018-12-18 22:43:20,242 - logs/main.logs:15 - WARNING - logs/main.logs
2018-12-18 22:47:31,135 - logs/main.logs:15 - WARNING - logs/main.logs
2018-12-18 22:53:02,186 - logs/main.logs:15 - WARNING - logs/main.logs
2018-12-18 22:54:46,067 - logs/main.logs:15 - WARNING - logs/main.logs
2018-12-18 22:59:26,427 - logs/main.logs:15 - WARNING - logs/main.logs
2018-12-18 23:21:30,714 - logs/main.logs:15 - WARNING - logs/main.logs
2018-12-18 23:26:39,771 - logs/main.logs:15 - WARNING - logs/main.logs
2018-12-18 23:28:51,750 - logs/main.logs:15 - WARNING - logs/main.logs
2018-12-18 23:29:35,032 - logs/main.logs:15 - WARNING - logs/main.logs
2018-12-18 23:30:15,987 - logs/main.logs:15 - WARNING - logs/main.logs
2018-12-18 23:31:45,263 - logs/main.logs:15 - WARNING - logs/main.logs
2018-12-18 23:32:46,524 - logs/main.logs:15 - WARNING - logs/main.logs
2018-12-18 23:34:13,193 - logs/main.logs:15 - WARNING - logs/main.logs
2018-12-18 23:39:34,811 - logs/main.logs:15 - WARNING - logs/main.logs
2018-12-19 08:31:11,771 - logs/main.logs:15 - WARNING - logs/main.logs
2018-12-19 09:20:38,722 - logs/main.logs:15 - WARNING - logs/main.logs
2018-12-19 10:24:10,705 - logs/main.logs:15 - WARNING - logs/main.logs
2018-12-19 10:51:17,174 - logs/main.logs:15 - WARNING - logs/main.logs
2018-12-19 10:55:17,311 - logs/main.logs:15 - WARNING - logs/main.logs
2018-12-19 10:57:04,116 - logs/main.logs:61 - ERROR - TABS:
Traceback (most recent call last):
  File "/home/andre/aion/data_science/bokeh/aion_analytics/scripts/dashboards/streaming/hashrate.py", line 108, in hashrate_tab
    dmap_diff = hv.DynamicMap(difficulty_plot(),datashade=True)\
  File "/home/andre/anaconda3/envs/bokeh_aion_analytics/lib/python3.5/site-packages/holoviews/core/spaces.py", line 760, in __init__
    if self.callback.noargs:
  File "/home/andre/anaconda3/envs/bokeh_aion_analytics/lib/python3.5/site-packages/holoviews/core/spaces.py", line 525, in noargs
    return self.argspec == noargs
  File "/home/andre/anaconda3/envs/bokeh_aion_analytics/lib/python3.5/site-packages/holoviews/core/spaces.py", line 519, in argspec
    return util.argspec(self.callable)
  File "/home/andre/anaconda3/envs/bokeh_aion_analytics/lib/python3.5/site-packages/holoviews/core/util.py", line 273, in argspec
    return argspec(callable_obj.__call__)
AttributeError: 'NoneType' object has no attribute '__call__'

During handling of the above exception, another exception occurred:

Traceback (most recent call last):
  File "/home/andre/aion/data_science/bokeh/aion_analytics/main.py", line 55, in aion_analytics
    hr = yield hashrate_tab()
  File "/home/andre/anaconda3/envs/bokeh_aion_analytics/lib/python3.5/site-packages/tornado/gen.py", line 1133, in run
    value = future.result()
  File "/home/andre/anaconda3/envs/bokeh_aion_analytics/lib/python3.5/asyncio/futures.py", line 294, in result
    raise self._exception
  File "/home/andre/anaconda3/envs/bokeh_aion_analytics/lib/python3.5/site-packages/tornado/gen.py", line 307, in wrapper
    result = func(*args, **kwargs)
  File "/home/andre/anaconda3/envs/bokeh_aion_analytics/lib/python3.5/types.py", line 243, in wrapped
    coro = func(*args, **kwargs)
  File "/home/andre/aion/data_science/bokeh/aion_analytics/scripts/dashboards/streaming/hashrate.py", line 135, in hashrate_tab
    return tab_error_flag('hashrate')
  File "/home/andre/aion/data_science/bokeh/aion_analytics/scripts/utils/myutils.py", line 89, in tab_error_flag
    print('IN POOLMINER')
BrokenPipeError: [Errno 32] Broken pipe
2018-12-19 12:46:20,973 - logs/main.logs:15 - WARNING - logs/main.logs
2018-12-19 13:01:56,699 - logs/main.logs:15 - WARNING - logs/main.logs
2018-12-19 13:04:21,051 - logs/main.logs:61 - ERROR - TABS:
Traceback (most recent call last):
  File "/home/andre/aion/data_science/bokeh/aion_analytics/scripts/dashboards/streaming/hashrate.py", line 108, in hashrate_tab
    dmap_diff = hv.DynamicMap(difficulty_plot(),datashade=True)\
  File "/home/andre/anaconda3/envs/bokeh_aion_analytics/lib/python3.5/site-packages/holoviews/core/spaces.py", line 760, in __init__
    if self.callback.noargs:
  File "/home/andre/anaconda3/envs/bokeh_aion_analytics/lib/python3.5/site-packages/holoviews/core/spaces.py", line 525, in noargs
    return self.argspec == noargs
  File "/home/andre/anaconda3/envs/bokeh_aion_analytics/lib/python3.5/site-packages/holoviews/core/spaces.py", line 519, in argspec
    return util.argspec(self.callable)
  File "/home/andre/anaconda3/envs/bokeh_aion_analytics/lib/python3.5/site-packages/holoviews/core/util.py", line 273, in argspec
    return argspec(callable_obj.__call__)
AttributeError: 'NoneType' object has no attribute '__call__'

During handling of the above exception, another exception occurred:

Traceback (most recent call last):
  File "/home/andre/aion/data_science/bokeh/aion_analytics/main.py", line 55, in aion_analytics
    hr = yield hashrate_tab()
  File "/home/andre/anaconda3/envs/bokeh_aion_analytics/lib/python3.5/site-packages/tornado/gen.py", line 1133, in run
    value = future.result()
  File "/home/andre/anaconda3/envs/bokeh_aion_analytics/lib/python3.5/asyncio/futures.py", line 294, in result
    raise self._exception
  File "/home/andre/anaconda3/envs/bokeh_aion_analytics/lib/python3.5/site-packages/tornado/gen.py", line 307, in wrapper
    result = func(*args, **kwargs)
  File "/home/andre/anaconda3/envs/bokeh_aion_analytics/lib/python3.5/types.py", line 243, in wrapped
    coro = func(*args, **kwargs)
  File "/home/andre/aion/data_science/bokeh/aion_analytics/scripts/dashboards/streaming/hashrate.py", line 135, in hashrate_tab
    return tab_error_flag('hashrate')
  File "/home/andre/aion/data_science/bokeh/aion_analytics/scripts/utils/myutils.py", line 89, in tab_error_flag
    print('IN POOLMINER')
BrokenPipeError: [Errno 32] Broken pipe
2018-12-19 13:07:30,850 - logs/main.logs:15 - WARNING - logs/main.logs
2018-12-19 13:09:41,559 - logs/main.logs:61 - ERROR - TABS:
Traceback (most recent call last):
  File "/home/andre/aion/data_science/bokeh/aion_analytics/scripts/dashboards/streaming/hashrate.py", line 108, in hashrate_tab
    dmap_diff = hv.DynamicMap(difficulty_plot(),datashade=True)\
  File "/home/andre/anaconda3/envs/bokeh_aion_analytics/lib/python3.5/site-packages/holoviews/core/spaces.py", line 760, in __init__
    if self.callback.noargs:
  File "/home/andre/anaconda3/envs/bokeh_aion_analytics/lib/python3.5/site-packages/holoviews/core/spaces.py", line 525, in noargs
    return self.argspec == noargs
  File "/home/andre/anaconda3/envs/bokeh_aion_analytics/lib/python3.5/site-packages/holoviews/core/spaces.py", line 519, in argspec
    return util.argspec(self.callable)
  File "/home/andre/anaconda3/envs/bokeh_aion_analytics/lib/python3.5/site-packages/holoviews/core/util.py", line 273, in argspec
    return argspec(callable_obj.__call__)
AttributeError: 'NoneType' object has no attribute '__call__'

During handling of the above exception, another exception occurred:

Traceback (most recent call last):
  File "/home/andre/aion/data_science/bokeh/aion_analytics/main.py", line 55, in aion_analytics
    hr = yield hashrate_tab()
  File "/home/andre/anaconda3/envs/bokeh_aion_analytics/lib/python3.5/site-packages/tornado/gen.py", line 1133, in run
    value = future.result()
  File "/home/andre/anaconda3/envs/bokeh_aion_analytics/lib/python3.5/asyncio/futures.py", line 294, in result
    raise self._exception
  File "/home/andre/anaconda3/envs/bokeh_aion_analytics/lib/python3.5/site-packages/tornado/gen.py", line 307, in wrapper
    result = func(*args, **kwargs)
  File "/home/andre/anaconda3/envs/bokeh_aion_analytics/lib/python3.5/types.py", line 243, in wrapped
    coro = func(*args, **kwargs)
  File "/home/andre/aion/data_science/bokeh/aion_analytics/scripts/dashboards/streaming/hashrate.py", line 135, in hashrate_tab
    return tab_error_flag('hashrate')
  File "/home/andre/aion/data_science/bokeh/aion_analytics/scripts/utils/myutils.py", line 89, in tab_error_flag
    print('IN POOLMINER')
BrokenPipeError: [Errno 32] Broken pipe
2018-12-19 13:13:55,704 - logs/main.logs:15 - WARNING - logs/main.logs
2018-12-19 13:31:50,667 - logs/main.logs:15 - WARNING - logs/main.logs
2018-12-19 13:32:11,331 - logs/main.logs:61 - ERROR - TABS:
Traceback (most recent call last):
  File "/home/andre/aion/data_science/bokeh/aion_analytics/scripts/dashboards/streaming/poolminer.py", line 219, in poolminer_tab
    all_plot = renderer.get_plot(dmap_all)
  File "/home/andre/anaconda3/envs/bokeh_aion_analytics/lib/python3.5/site-packages/holoviews/plotting/bokeh/renderer.py", line 162, in get_plot
    plot = super(BokehRenderer, self_or_cls).get_plot(obj, renderer, **kwargs)
  File "/home/andre/anaconda3/envs/bokeh_aion_analytics/lib/python3.5/site-packages/holoviews/plotting/renderer.py", line 182, in get_plot
    initialize_dynamic(obj)
  File "/home/andre/anaconda3/envs/bokeh_aion_analytics/lib/python3.5/site-packages/holoviews/plotting/util.py", line 244, in initialize_dynamic
    dmap[dmap._initial_key()]
  File "/home/andre/anaconda3/envs/bokeh_aion_analytics/lib/python3.5/site-packages/holoviews/core/spaces.py", line 1132, in __getitem__
    val = self._execute_callback(*tuple_key)
  File "/home/andre/anaconda3/envs/bokeh_aion_analytics/lib/python3.5/site-packages/holoviews/core/spaces.py", line 911, in _execute_callback
    retval = self.callback(*args, **kwargs)
  File "/home/andre/anaconda3/envs/bokeh_aion_analytics/lib/python3.5/site-packages/holoviews/core/spaces.py", line 574, in __call__
    ret = self.callable(*args, **kwargs)
  File "/home/andre/anaconda3/envs/bokeh_aion_analytics/lib/python3.5/site-packages/holoviews/util/__init__.py", line 437, in dynamic_operation
    return self._process(map_obj[key], key)
  File "/home/andre/anaconda3/envs/bokeh_aion_analytics/lib/python3.5/site-packages/holoviews/core/spaces.py", line 1132, in __getitem__
    val = self._execute_callback(*tuple_key)
  File "/home/andre/anaconda3/envs/bokeh_aion_analytics/lib/python3.5/site-packages/holoviews/core/spaces.py", line 911, in _execute_callback
    retval = self.callback(*args, **kwargs)
  File "/home/andre/anaconda3/envs/bokeh_aion_analytics/lib/python3.5/site-packages/holoviews/core/spaces.py", line 574, in __call__
    ret = self.callable(*args, **kwargs)
  File "/home/andre/aion/data_science/bokeh/aion_analytics/scripts/dashboards/streaming/poolminer.py", line 87, in load_data
    logger.warning('load_data head:%s', self.df.head())
AttributeError: 'NoneType' object has no attribute 'head'

During handling of the above exception, another exception occurred:

Traceback (most recent call last):
  File "/home/andre/aion/data_science/bokeh/aion_analytics/main.py", line 54, in aion_analytics
    pm = yield poolminer_tab()
  File "/home/andre/anaconda3/envs/bokeh_aion_analytics/lib/python3.5/site-packages/tornado/gen.py", line 1133, in run
    value = future.result()
  File "/home/andre/anaconda3/envs/bokeh_aion_analytics/lib/python3.5/asyncio/futures.py", line 294, in result
    raise self._exception
  File "/home/andre/anaconda3/envs/bokeh_aion_analytics/lib/python3.5/site-packages/tornado/gen.py", line 307, in wrapper
    result = func(*args, **kwargs)
  File "/home/andre/anaconda3/envs/bokeh_aion_analytics/lib/python3.5/types.py", line 243, in wrapped
    coro = func(*args, **kwargs)
  File "/home/andre/aion/data_science/bokeh/aion_analytics/scripts/dashboards/streaming/poolminer.py", line 251, in poolminer_tab
    return tab_error_flag('poolminer')
  File "/home/andre/aion/data_science/bokeh/aion_analytics/scripts/utils/myutils.py", line 89, in tab_error_flag
    print('IN POOLMINER')
BrokenPipeError: [Errno 32] Broken pipe
2018-12-19 13:35:36,538 - logs/main.logs:15 - WARNING - logs/main.logs
2018-12-19 13:44:17,157 - logs/main.logs:15 - WARNING - logs/main.logs
2018-12-19 14:09:02,439 - logs/main.logs:15 - WARNING - logs/main.logs
2018-12-19 14:28:17,258 - logs/main.logs:15 - WARNING - logs/main.logs
2018-12-19 14:42:40,136 - logs/main.logs:15 - WARNING - logs/main.logs
2018-12-19 14:47:33,880 - logs/main.logs:15 - WARNING - logs/main.logs
2018-12-19 14:56:47,124 - logs/main.logs:15 - WARNING - logs/main.logs
2018-12-19 14:59:17,452 - logs/main.logs:61 - ERROR - TABS:
Traceback (most recent call last):
  File "/home/andre/aion/data_science/bokeh/aion_analytics/scripts/dashboards/streaming/hashrate.py", line 108, in hashrate_tab
    dmap_diff = hv.DynamicMap(difficulty_plot(),datashade=True)\
  File "/home/andre/anaconda3/envs/bokeh_aion_analytics/lib/python3.5/site-packages/holoviews/core/spaces.py", line 760, in __init__
    if self.callback.noargs:
  File "/home/andre/anaconda3/envs/bokeh_aion_analytics/lib/python3.5/site-packages/holoviews/core/spaces.py", line 525, in noargs
    return self.argspec == noargs
  File "/home/andre/anaconda3/envs/bokeh_aion_analytics/lib/python3.5/site-packages/holoviews/core/spaces.py", line 519, in argspec
    return util.argspec(self.callable)
  File "/home/andre/anaconda3/envs/bokeh_aion_analytics/lib/python3.5/site-packages/holoviews/core/util.py", line 273, in argspec
    return argspec(callable_obj.__call__)
AttributeError: 'NoneType' object has no attribute '__call__'

During handling of the above exception, another exception occurred:

Traceback (most recent call last):
  File "/home/andre/aion/data_science/bokeh/aion_analytics/main.py", line 55, in aion_analytics
    hr = yield hashrate_tab()
  File "/home/andre/anaconda3/envs/bokeh_aion_analytics/lib/python3.5/site-packages/tornado/gen.py", line 1133, in run
    value = future.result()
  File "/home/andre/anaconda3/envs/bokeh_aion_analytics/lib/python3.5/asyncio/futures.py", line 294, in result
    raise self._exception
  File "/home/andre/anaconda3/envs/bokeh_aion_analytics/lib/python3.5/site-packages/tornado/gen.py", line 307, in wrapper
    result = func(*args, **kwargs)
  File "/home/andre/anaconda3/envs/bokeh_aion_analytics/lib/python3.5/types.py", line 243, in wrapped
    coro = func(*args, **kwargs)
  File "/home/andre/aion/data_science/bokeh/aion_analytics/scripts/dashboards/streaming/hashrate.py", line 135, in hashrate_tab
    return tab_error_flag('hashrate')
  File "/home/andre/aion/data_science/bokeh/aion_analytics/scripts/utils/myutils.py", line 89, in tab_error_flag
    print('IN POOLMINER')
BrokenPipeError: [Errno 32] Broken pipe
2018-12-19 15:17:07,438 - logs/main.logs:15 - WARNING - logs/main.logs
2018-12-19 15:18:32,280 - logs/main.logs:15 - WARNING - logs/main.logs
2018-12-19 15:23:47,522 - logs/main.logs:15 - WARNING - logs/main.logs
2018-12-19 15:26:52,755 - logs/main.logs:61 - ERROR - TABS:
Traceback (most recent call last):
  File "/home/andre/aion/data_science/bokeh/aion_analytics/scripts/dashboards/streaming/hashrate.py", line 108, in hashrate_tab
    dmap_diff = hv.DynamicMap(difficulty_plot(),datashade=True)\
  File "/home/andre/anaconda3/envs/bokeh_aion_analytics/lib/python3.5/site-packages/holoviews/core/spaces.py", line 760, in __init__
    if self.callback.noargs:
  File "/home/andre/anaconda3/envs/bokeh_aion_analytics/lib/python3.5/site-packages/holoviews/core/spaces.py", line 525, in noargs
    return self.argspec == noargs
  File "/home/andre/anaconda3/envs/bokeh_aion_analytics/lib/python3.5/site-packages/holoviews/core/spaces.py", line 519, in argspec
    return util.argspec(self.callable)
  File "/home/andre/anaconda3/envs/bokeh_aion_analytics/lib/python3.5/site-packages/holoviews/core/util.py", line 273, in argspec
    return argspec(callable_obj.__call__)
AttributeError: 'NoneType' object has no attribute '__call__'

During handling of the above exception, another exception occurred:

Traceback (most recent call last):
  File "/home/andre/aion/data_science/bokeh/aion_analytics/main.py", line 55, in aion_analytics
    hr = yield hashrate_tab()
  File "/home/andre/anaconda3/envs/bokeh_aion_analytics/lib/python3.5/site-packages/tornado/gen.py", line 1133, in run
    value = future.result()
  File "/home/andre/anaconda3/envs/bokeh_aion_analytics/lib/python3.5/asyncio/futures.py", line 294, in result
    raise self._exception
  File "/home/andre/anaconda3/envs/bokeh_aion_analytics/lib/python3.5/site-packages/tornado/gen.py", line 307, in wrapper
    result = func(*args, **kwargs)
  File "/home/andre/anaconda3/envs/bokeh_aion_analytics/lib/python3.5/types.py", line 243, in wrapped
    coro = func(*args, **kwargs)
  File "/home/andre/aion/data_science/bokeh/aion_analytics/scripts/dashboards/streaming/hashrate.py", line 135, in hashrate_tab
    return tab_error_flag('hashrate')
  File "/home/andre/aion/data_science/bokeh/aion_analytics/scripts/utils/myutils.py", line 89, in tab_error_flag
    print('IN POOLMINER')
BrokenPipeError: [Errno 32] Broken pipe
2018-12-19 15:27:38,513 - logs/main.logs:15 - WARNING - logs/main.logs
2018-12-19 15:32:13,217 - logs/main.logs:15 - WARNING - logs/main.logs
2018-12-19 15:34:08,322 - logs/main.logs:15 - WARNING - logs/main.logs
2018-12-19 15:50:00,011 - logs/main.logs:15 - WARNING - logs/main.logs
2018-12-19 15:57:22,006 - logs/main.logs:15 - WARNING - logs/main.logs
2018-12-19 15:58:54,397 - logs/main.logs:15 - WARNING - logs/main.logs
2018-12-19 16:18:55,582 - logs/main.logs:15 - WARNING - logs/main.logs
2018-12-19 17:19:40,716 - logs/main.logs:15 - WARNING - logs/main.logs
2018-12-19 17:28:27,755 - logs/main.logs:15 - WARNING - logs/main.logs
2018-12-19 17:40:22,645 - logs/main.logs:15 - WARNING - logs/main.logs
2018-12-19 17:42:13,672 - logs/main.logs:15 - WARNING - logs/main.logs
2018-12-19 17:44:14,173 - logs/main.logs:15 - WARNING - logs/main.logs
2018-12-19 17:44:48,428 - logs/main.logs:61 - ERROR - TABS:
Traceback (most recent call last):
  File "/home/andre/aion/data_science/bokeh/aion_analytics/scripts/dashboards/streaming/hashrate.py", line 108, in hashrate_tab
    dmap_diff = hv.DynamicMap(difficulty_plot(),datashade=True)\
  File "/home/andre/anaconda3/envs/bokeh_aion_analytics/lib/python3.5/site-packages/holoviews/core/spaces.py", line 760, in __init__
    if self.callback.noargs:
  File "/home/andre/anaconda3/envs/bokeh_aion_analytics/lib/python3.5/site-packages/holoviews/core/spaces.py", line 525, in noargs
    return self.argspec == noargs
  File "/home/andre/anaconda3/envs/bokeh_aion_analytics/lib/python3.5/site-packages/holoviews/core/spaces.py", line 519, in argspec
    return util.argspec(self.callable)
  File "/home/andre/anaconda3/envs/bokeh_aion_analytics/lib/python3.5/site-packages/holoviews/core/util.py", line 273, in argspec
    return argspec(callable_obj.__call__)
AttributeError: 'NoneType' object has no attribute '__call__'

During handling of the above exception, another exception occurred:

Traceback (most recent call last):
  File "/home/andre/aion/data_science/bokeh/aion_analytics/main.py", line 55, in aion_analytics
    hr = yield hashrate_tab()
  File "/home/andre/anaconda3/envs/bokeh_aion_analytics/lib/python3.5/site-packages/tornado/gen.py", line 1133, in run
    value = future.result()
  File "/home/andre/anaconda3/envs/bokeh_aion_analytics/lib/python3.5/asyncio/futures.py", line 294, in result
    raise self._exception
  File "/home/andre/anaconda3/envs/bokeh_aion_analytics/lib/python3.5/site-packages/tornado/gen.py", line 307, in wrapper
    result = func(*args, **kwargs)
  File "/home/andre/anaconda3/envs/bokeh_aion_analytics/lib/python3.5/types.py", line 243, in wrapped
    coro = func(*args, **kwargs)
  File "/home/andre/aion/data_science/bokeh/aion_analytics/scripts/dashboards/streaming/hashrate.py", line 135, in hashrate_tab
    return tab_error_flag('hashrate')
  File "/home/andre/aion/data_science/bokeh/aion_analytics/scripts/utils/myutils.py", line 89, in tab_error_flag
    print('IN POOLMINER')
BrokenPipeError: [Errno 32] Broken pipe
