2018-12-07 18:47:54,757 - logs/pythonCassandra.logs - WARNING - logs/pythonCassandra.logs
2018-12-07 19:04:17,471 - logs/pythonCassandra.logs - WARNING - logs/pythonCassandra.logs
2018-12-07 19:06:24,331 - logs/pythonCassandra.logs - WARNING - logs/pythonCassandra.logs
2018-12-07 19:08:39,435 - logs/pythonCassandra.logs - WARNING - logs/pythonCassandra.logs
2018-12-07 19:10:01,420 - logs/pythonCassandra.logs - WARNING - logs/pythonCassandra.logs
2018-12-07 19:17:52,294 - logs/pythonCassandra.logs - WARNING - logs/pythonCassandra.logs
2018-12-07 19:20:16,746 - logs/pythonCassandra.logs - WARNING - logs/pythonCassandra.logs
2018-12-08 11:15:01,910 - logs/pythonCassandra.logs - WARNING - logs/pythonCassandra.logs
2018-12-08 12:02:28,626 - logs/pythonCassandra.logs - WARNING - logs/pythonCassandra.logs
2018-12-08 12:05:04,128 - logs/pythonCassandra.logs - WARNING - logs/pythonCassandra.logs
2018-12-08 12:08:21,595 - logs/pythonCassandra.logs - WARNING - logs/pythonCassandra.logs
2018-12-08 12:09:22,780 - logs/pythonCassandra.logs - WARNING - logs/pythonCassandra.logs
2018-12-08 12:13:35,295 - logs/pythonCassandra.logs - WARNING - logs/pythonCassandra.logs
2018-12-08 12:16:45,491 - logs/pythonCassandra.logs - WARNING - logs/pythonCassandra.logs
2018-12-08 12:18:07,986 - logs/pythonCassandra.logs - WARNING - logs/pythonCassandra.logs
2018-12-08 12:18:37,147 - logs/pythonCassandra.logs - ERROR - Insert error:
Traceback (most recent call last):
  File "/home/andre/aion/data_science/bokeh/aion_analytics/scripts/utils/pythonCassandra.py", line 155, in insert_data_block
    self.session.execute(batch)
  File "cassandra/cluster.py", line 2030, in cassandra.cluster.Session.execute (cassandra/cluster.c:35551)
  File "cassandra/cluster.py", line 3844, in cassandra.cluster.ResponseFuture.result (cassandra/cluster.c:74495)
cassandra.cluster.NoHostAvailable: ('Unable to complete the operation against any hosts', {})
2018-12-08 12:20:48,687 - logs/pythonCassandra.logs - WARNING - logs/pythonCassandra.logs
2018-12-08 12:22:10,937 - logs/pythonCassandra.logs - WARNING - logs/pythonCassandra.logs
2018-12-08 12:22:34,642 - logs/pythonCassandra.logs - ERROR - Insert error:
Traceback (most recent call last):
  File "/home/andre/aion/data_science/bokeh/aion_analytics/scripts/utils/pythonCassandra.py", line 155, in insert_data_block
    self.session.execute(batch)
  File "cassandra/cluster.py", line 2030, in cassandra.cluster.Session.execute (cassandra/cluster.c:35551)
  File "cassandra/cluster.py", line 3844, in cassandra.cluster.ResponseFuture.result (cassandra/cluster.c:74495)
cassandra.cluster.NoHostAvailable: ('Unable to complete the operation against any hosts', {})
